Workbook

Sheet Sheet1
A2: FUND | B2: PLAY
B4: Sum of Shares | F4: Sum of Weight (%) | J4: Average of Price
B5: 45657 | C5: 45930 | D5: 45961 | E5: 45987 | F5: 45657 | G5: 45930 | H5: 45961 | I5: 45987 | J5: 45657 | K5: 45930 | L5: 45961 | M5: 45987
A6: ADVANCED MICRO DEVICES INC | B6: 14759 | C6: 29087 | D6: 29087 | E6: 31566 | F6: 3.9 | G6: 6.49 | H6: 10.08 | I6: 9.31 | J6: 120.79 | K6: 161.79 | L6: 256.12 | M6: 214.24 | N6: =M6/J6-1 -> 0.77365676
A7: SAMSUNG ELECTRONICS LTD | B7: 38388 | C7: 73018 | D7: 73018 | E7: 79200 | F7: 3.04 | G7: 6.03 | H7: 7.45 | I7: 7.65 | J7: 36.14 | K7: 59.8 | L7: 75.45 | M7: 70.14 | N7: =M7/J7-1 -> 0.94078583
A8: APPLE INC | B8: 11336 | C8: 17690 | D8: 17690 | E8: 19195 | F8: 6.21 | G8: 6.22 | H8: 6.47 | I8: 7.33 | J8: 250.42 | K8: 254.63 | L8: 270.37 | M8: 277.55 | N8: =M8/J8-1 -> 0.10833799
A9: NVIDIA CORP | B9: 19373 | C9: 24895 | D9: 24895 | E9: 27023 | F9: 5.69 | G9: 6.41 | H9: 6.82 | I9: 6.7 | J9: 134.29 | K9: 186.58 | L9: 202.49 | M9: 180.26 | N9: =M9/J9-1 -> 0.34231886
A10: ELECTRONIC ARTS INC | B10: 13113 | C10: 18684 | D10: 18684 | E10: 20274 | F10: 4.2 | G10: 5.2 | H10: 5.06 | I10: 5.63 | J10: 146.3 | K10: 201.7 | L10: 200.06 | M10: 201.92 | N10: =M10/J10-1 -> 0.38017772
A11: NETFLIX INC | B11: 3619 | C11: 2978 | D11: 2978 | E11: 32320 | F11: 7.06 | G11: 4.93 | H11: 4.51 | I11: 4.72 | J11: 891.32 | K11: 1198.92 | L11: 1118.86 | M11: 106.14 | N11: =M11/J11-1 -> -0.88091819
A12: TAKE TWO INTERACTIVE SOFTWARE INC | B12: 9710 | C12: 12135 | D12: 12135 | E12: 13170 | F12: 3.91 | G12: 4.33 | H12: 4.21 | I12: 4.42 | J12: 184.08 | K12: 258.36 | L12: 256.37 | M12: 243.63 | N12: =M12/J12-1 -> 0.32350065
A13: NINTENDO LTD | B13: 32400 | C13: 34100 | D13: 34100 | E13: 37000 | F13: 4.18 | G13: 4.08 | H13: 3.91 | I13: 4.31 | J13: 58.95 | K13: 86.7 | L13: 84.68 | M13: 84.61 | N13: =M13/J13-1 -> 0.43528414
A14: ROBLOX CORP CLASS A | B14: 32506 | C14: 30425 | D14: 30425 | E14: 33011 | F14: 4.12 | G14: 5.82 | H14: 4.68 | I14: 4.21 | J14: 57.86 | K14: 138.52 | L14: 113.72 | M14: 92.73 | N14: =M14/J14-1 -> 0.6026616
A15: XIAOMI CORP | B15: 808600 | C15: 527000 | D15: 527000 | E15: 571200 | F15: 7.86 | G15: 5.05 | H15: 3.96 | I15: 4.05 | J15: 4.44 | K15: 6.94 | L15: 5.56 | M15: 5.16 | N15: =M15/J15-1 -> 0.16216216
A16: SPOTIFY TECHNOLOGY SA | B16: 5768 | C16: 4112 | D16: 4112 | E16: 4462 | F16: 5.65 | G16: 3.96 | H16: 3.64 | I16: 3.64 | J16: 447.38 | K16: 698 | L16: 655.32 | M16: 592.69 | N16: =M16/J16-1 -> 0.32480218
A17: REDDIT INC CLASS A | C17: 10066 | D17: 10066 | E17: 10928 | G17: 3.19 | H17: 2.84 | I17: 3.12 | K17: 229.99 | L17: 208.95 | M17: 207.56 | N17: =M17/J17-1 -> #DIV/0!
A18: ARISTOCRAT LEISURE LTD | B18: 38986 | C18: 51762 | D18: 51762 | E18: 56119 | F18: 3.61 | G18: 3.31 | H18: 2.9 | I18: 2.94 | J18: 42.33 | K18: 46.38 | L18: 41.47 | M18: 38.09 | N18: =M18/J18-1 -> -0.10016537
A19: ZOOM COMMUNICATIONS INC CLASS A | B19: 15843 | C19: 21723 | D19: 21723 | E19: 23561 | F19: 2.83 | G19: 2.47 | H19: 2.56 | I19: 2.74 | J19: 81.61 | K19: 82.5 | L19: 87.23 | M19: 84.43 | N19: =M19/J19-1 -> 0.034554589
A20: TRADE DESK INC CLASS A | B20: 19441 | C20: 37041 | D20: 37041 | E20: 40207 | F20: 5 | G20: 2.51 | H20: 2.52 | I20: 2.16 | J20: 117.53 | K20: 49.01 | L20: 50.28 | M20: 39.11 | N20: =M20/J20-1 -> -0.6672339
A21: LOGITECH INTERNATIONAL SA | B21: 9439 | C21: 12218 | D21: 12218 | E21: 13223 | F21: 1.71 | G21: 1.84 | H21: 1.99 | I21: 2.03 | J21: 82.8 | K21: 109.07 | L21: 120.44 | M21: 111.71 | N21: =M21/J21-1 -> 0.34915459
A22: KONAMI GROUP CORP | B22: 6300 | C22: 8500 | D22: 8500 | E22: 9200 | F22: 1.3 | G22: 1.7 | H22: 1.92 | I22: 1.92 | J22: 94.17 | K22: 144.56 | L22: 167.08 | M22: 151.89 | N22: =M22/J22-1 -> 0.61293406
A23: PINTEREST INC CLASS A | B23: 36401 | C23: 49140 | D23: 49140 | E23: 53315 | F23: 2.31 | G23: 2.18 | H23: 2.2 | I23: 1.88 | J23: 29 | K23: 32.17 | L23: 33.1 | M23: 25.57 | N23: =M23/J23-1 -> -0.11827586
A24: ROKU INC CLASS A | B24: 7723 | C24: 10688 | D24: 10688 | E24: 11622 | F24: 1.26 | G24: 1.48 | H24: 1.53 | I24: 1.53 | J24: 74.34 | K24: 100.13 | L24: 106.13 | M24: 95.63 | N24: =M24/J24-1 -> 0.28638687
A25: LENOVO GROUP LTD | B25: 520000 | C25: 708000 | D25: 708000 | E25: 766000 | F25: 1.48 | G25: 1.45 | H25: 1.4 | I25: 1.31 | J25: 1.3 | K25: 1.48 | L25: 1.46 | M25: 1.25 | N25: =M25/J25-1 -> -0.038461538
A26: EVOLUTION | B26: 11803 | C26: 12331 | D26: 12331 | E26: 13369 | F26: 1.99 | G26: 1.4 | H26: 1.12 | I26: 1.24 | J26: 77.18 | K26: 82.23 | L26: 66.92 | M26: 67.33 | N26: =M26/J26-1 -> -0.12762374
A27: NEXON LTD | B27: 21300 | C27: 34100 | D27: 34100 | E27: 37000 | F27: 0.7 | G27: 1.03 | H27: 0.94 | I27: 1.2 | J27: 15.12 | K27: 21.99 | L27: 20.45 | M27: 23.59 | N27: =M27/J27-1 -> 0.56018519
A28: CAPCOM LTD | B28: 22900 | C28: 31000 | D28: 31000 | E28: 33600 | F28: 1.11 | G28: 1.17 | H28: 1.1 | I28: 1.12 | J28: 22.1 | K28: 27.24 | L28: 26.19 | M28: 24.25 | N28: =M28/J28-1 -> 0.097285068
A29: SNAP INC CLASS A | B29: 66688 | C29: 98070 | D29: 98070 | E29: 106261 | F29: 1.57 | G29: 1.04 | H29: 1.03 | I29: 1.11 | J29: 10.77 | K29: 7.71 | L29: 7.8 | M29: 7.61 | N29: =M29/J29-1 -> -0.29340761
... A32: DUOLINGO INC CLASS A | B32: 2189 | C32: 3245 | D32: 3245 | E32: 3522 | F32: 1.55 | G32: 1.44 | H32: 1.19 | I32: 0.91 | J32: 324.23 | K32: 321.84 | L32: 270.64 | M32: 188.43 | N32: =M32/J32-1 -> -0.41883848
A33: LIFE360 INC | C33: 6334 | D33: 6334 | E33: 6866 | G33: 0.93 | H33: 0.85 | I33: 0.74 | K33: 106.3 | L33: 98.71 | M33: 78.46 | N33: =M33/J33-1 -> #DIV/0!
A34: KRAFTON INC | B34: 2108 | C34: 2626 | D34: 2626 | E34: 2814 | F34: 0.98 | G34: 0.76 | H34: 0.69 | I34: 0.69 | J34: 212.27 | K34: 208.47 | L34: 193.72 | M34: 177.39 | N34: =M34/J34-1 -> -0.16431903
A35: SQUARE ENIX HLDG LTD | B35: 5600 | C35: 22800 | D35: 22800 | E35: 24800 | F35: 0.48 | G35: 0.68 | H35: 0.6 | I35: 0.68 | J35: 39.11 | K35: 21.55 | L35: 19.38 | M35: 19.81 | N35: =M35/J35-1 -> -0.49347993
A36: CD PROJEKT SA | B36: 4291 | C36: 5816 | D36: 5816 | E36: 6233 | F36: 0.44 | G36: 0.6 | H36: 0.54 | I36: 0.57 | J36: 46.35 | K36: 74.56 | L36: 68.78 | M36: 66.56 | N36: =M36/J36-1 -> 0.4360302
A37: GRAND CANYON EDUCATION INC | B37: 1841 | C37: 2352 | D37: 2352 | E37: 2521 | F37: 0.66 | G37: 0.71 | H37: 0.6 | I37: 0.54 | J37: 163.8 | K37: 219.52 | L37: 188.3 | M37: 156.43 | N37: =M37/J37-1 -> -0.044993895
A38: SOUNDHOUND AI INC CLASS A | B38: 18055 | C38: 30562 | D38: 30562 | E38: 32752 | F38: 0.78 | G38: 0.68 | H38: 0.73 | I38: 0.53 | J38: 19.84 | K38: 16.08 | L38: 17.62 | M38: 11.82 | N38: =M38/J38-1 -> -0.40423387
A39: SANKYO LTD | B39: 13100 | C39: 18200 | D39: 18200 | E39: 19500 | F39: 0.39 | G39: 0.44 | H39: 0.43 | I39: 0.46 | J39: 13.54 | K39: 17.41 | L39: 17.37 | M39: 17 | N39: =M39/J39-1 -> 0.25553914
A40: AMBARELLA INC | B40: 2463 | C40: 3515 | D40: 3515 | E40: 3767 | F40: 0.39 | G40: 0.4 | H40: 0.41 | I40: 0.38 | J40: 72.74 | K40: 82.52 | L40: 85.23 | M40: 73.89 | N40: =M40/J40-1 -> 0.015809733
A41: STRIDE INC | B41: 2658 | C41: 3607 | D41: 3607 | E41: 3865 | F41: 0.6 | G41: 0.74 | H41: 0.33 | I41: 0.34 | J41: 103.93 | K41: 148.94 | L41: 68.04 | M41: 63.8 | N41: =M41/J41-1 -> -0.38612528
A42: SPORTRADAR GROUP AG CLASS A | C42: 9762 | D42: 9762 | E42: 10461 | G42: 0.36 | H42: 0.34 | I42: 0.31 | K42: 26.9 | L42: 25.61 | M42: 21.71 | N42: =M42/J42-1 -> #DIV/0!
A43: PELOTON INTERACTIVE CLASS A INC | B43: 21246 | C43: 31646 | D43: 31646 | E43: 33913 | F43: 0.4 | G43: 0.39 | H43: 0.31 | I43: 0.31 | J43: 8.7 | K43: 9 | L43: 7.26 | M43: 6.72 | N43: =M43/J43-1 -> -0.22758621
A44: SONOS INC | B44: 7494 | C44: 9927 | D44: 9927 | E44: 10638 | F44: 0.25 | G44: 0.22 | H44: 0.23 | I44: 0.27 | J44: 15.04 | K44: 15.8 | L44: 17.17 | M44: 18.63 | N44: =M44/J44-1 -> 0.23869681
...

Sheet Sheet9
A2: FUND | B2: DFEU
B4: Column Labels
B5: Sum of Weight (%) | I5: Sum of Price
A6: Row Labels | B6: 45930 | C6: 45989 | D6: 46022 | E6: 46024 | F6: 46028 | G6: 46031 | H6: 46051 | I6: 45930 | J6: 45989 | K6: 46022 | L6: 46024 | M6: 46028 | N6: 46031 | O6: 46051
A7: BAE SYSTEMS PLC | B7: 13.95 | C7: 13.56 | D7: 13.33 | E7: 13.27 | F7: 13.43 | G7: 13.57 | H7: 13.47 | I7: 23.59 | J7: 18.84 | K7: 19.63 | L7: 20.15 | M7: 21.73 | N7: 23.66 | O7: 22.77
A8: RHEINMETALL AG | B8: 14.85 | C8: 13.49 | D8: 13.42 | E8: 13.36 | F8: 13.62 | G8: 13.79 | H8: 13.45 | I8: 1984.5 | J8: 1480.5 | K8: 1561 | L8: 1602 | M8: 1740.5 | N8: 1900 | O8: 1795.5
A9: THALES SA | B9: 13.05 | C9: 13.43 | D9: 12.91 | E9: 12.81 | F9: 12.68 | G9: 12.63 | H9: 12.53 | I9: 266.6 | J9: 225.4 | K9: 229.8 | L9: 235 | M9: 247.9 | N9: 266 | O9: 255.9
A10: ROLLS-ROYCE HOLDINGS PLC | B10: 12.22 | C10: 13.29 | D10: 13.54 | E10: 13.72 | F10: 13.45 | G10: 12.95 | H10: 12.42 | I10: 13.63 | J10: 12.19 | K10: 13.17 | L10: 13.75 | M10: 14.37 | N10: 14.91 | O10: 13.86
A11: LEONARDO FINMECCANICA SPA | B11: 11.07 | C11: 11.69 | D11: 11.56 | E11: 11.69 | F11: 11.68 | G11: 11.62 | H11: 11.52 | I11: 54.02 | J11: 46.91 | K11: 49.16 | L11: 51.22 | M11: 54.58 | N11: 58.48 | O11: 56.22
A12: SAAB CLASS B | B12: 8.77 | C12: 8.91 | D12: 9.61 | E12: 9.73 | F12: 9.4 | G12: 10.4 | H12: 11.14 | I12: 51.99 | J12: 43.45 | K12: 49.65 | L12: 51.8 | M12: 55.41 | N12: 63.62 | O12: 66.05
A13: EUR CASH | B13: 0.14 | C13: 0.09 | D13: 0.19 | E13: 0.19 | F13: 1.95 | G13: 0.17 | H13: 4.56 | I13: 100 | J13: 100 | K13: 100 | L13: 100 | M13: 100 | N13: 100 | O13: 100
A14: BABCOCK INTERNATIONAL GROUP PLC | B14: 3.92 | C14: 4.04 | D14: 4.2 | E14: 4.18 | F14: 4.3 | G14: 4.22 | H14: 4.32 | I14: 15.24 | J14: 12.94 | K14: 14.24 | L14: 14.62 | M14: 16.03 | N14: 16.93 | O14: 16.81
A15: ASELSAN ELEKTRONIK SANAYI VE TICAR | B15: 2.64 | C15: 2.71 | D15: 3.15 | E15: 3.03 | F15: 3.19 | G15: 3.23 | H15: 3.69 | I15: 4.4 | J15: 3.72 | K15: 4.59 | L15: 4.55 | M15: 5.11 | N15: 5.58 | O15: 6.16
A16: DASSAULT AVIATION SA | B16: 2.63 | C16: 3.04 | D16: 2.9 | E16: 2.88 | F16: 2.81 | G16: 2.76 | H16: 2.95 | I16: 284.6 | J16: 270.6 | K16: 273.8 | L16: 280.4 | M16: 291.6 | N16: 308.6 | O16: 320
A17: HENSOLDT AG | B17: 3.37 | C17: 2.54 | D17: 2.57 | E17: 2.6 | F17: 2.62 | G17: 2.7 | H17: 2.58 | I17: 110.3 | J17: 68.35 | K17: 73.4 | L17: 76.4 | M17: 82 | N17: 91.3 | O17: 84.55
... A34: OTOKAR OTOMOTIV SAVUNMA SANAYI | B34: 0.01 | C34: 0.01 | D34: 0.01 | E34: 0.01 | F34: 0.01 | G34: 0.01 | H34: 0.01 | I34: 10.49 | J34: 9.3 | K34: 9.63 | L34: 9.51 | M34: 9.93 | N34: 10.15 | O34: 8.33
A35: STOXX 600 INDUS DEC 25 | B35: 0 | C35: 0 | I35: 1070.7 | J35: 1036.2
A36: GBP/EUR | F36: 0 | H36: 0 | M36: 1 | O36: 4
A37: STOXX 600 INDUS MAR 26 | D37: 0 | E37: 0 | F37: 0 | G37: 0 | H37: 0 | K37: 1076.9 | L37: 1083.5 | M37: 1120.7 | N37: 1145.5 | O37: 1131.9
A38: SEK/EUR | F38: 0 | H38: 0 | M38: 1 | O38: 4
A39: TRY/EUR | F39: 0 | H39: 0 | M39: 1 | O39: 4
A40: NOK/EUR | F40: 0 | H40: 0 | M40: 1 | O40: 4
A41: CZK/EUR | F41: 0 | H41: 0 | M41: 1 | O41: 4
A42: CZK CASH | B42: 0 | C42: 0 | D42: 0 | E42: 0 | F42: -0.01 | G42: 0 | H42: -0.02 | I42: 4.11 | J42: 4.14 | K42: 4.14 | L42: 4.14 | M42: 4.14 | N42: 4.12 | O42: 4.11
A43: NOK CASH | B43: 0 | C43: 0 | D43: 0 | E43: 0 | F43: -0.04 | G43: 0 | H43: -0.11 | I43: 8.53 | J43: 8.52 | K43: 8.44 | L43: 8.47 | M43: 8.51 | N43: 8.51 | O43: 8.73
A44: TRY CASH | B44: 0 | C44: 0.01 | D44: 0.01 | E44: 0.01 | F44: -0.11 | G44: 0 | H44: -0.31 | I44: 2.05 | J44: 2.03 | K44: 1.98 | L44: 1.98 | M44: 1.99 | N44: 1.99 | O44: 1.93
A45: SEK CASH | B45: 0 | C45: 0 | D45: 0 | E45: 0 | F45: 0 | G45: 0 | H45: -0.99 | I45: 9.05 | J45: 9.14 | K45: 9.24 | L45: 9.25 | M45: 9.28 | N45: 9.33 | O45: 9.46
A46: GBP CASH | B46: 0.01 | C46: 0.11 | D46: 0.01 | E46: 0.01 | F46: -1.26 | G46: 0.02 | H46: -2.89 | I46: 114.58 | J46: 114.17 | K46: 114.53 | L46: 114.88 | M46: 115.48 | N46: 115.27 | O46: 115.38
A47: Grand Total | B47: 99.98 | C47: 100.02 | D47: 100 | E47: 100.04 | F47: 100 | G47: 99.99 | H47: 99.98 | I47: 5043.97 | J47: 4320.05 | K47: 4472.97 | L47: 4562.06 | M47: 4809.73 | N47: 5076.42 | O47: 4919.76

Sheet Funds
A1: FUND | B1: Date | C1: Ticker | D1: Name | E1: Type | F1: Sector | G1: Asset Class | H1: Market Value | I1: Weight (%) | J1: Notional Value | K1: Shares | L1: Price | M1: Location | N1: Exchange | O1: Market Currency
A2: AINF | B2: 45657 | C2: AVGO | D2: BROADCOM INC | E2: EQUITY | F2: Information Technology | G2: Equity | H2: 944052.48 | I2: 6.29 | J2: 944052.48 | K2: 4072 | L2: 231.84 | M2: United States | N2: NASDAQ | O2: USD
A3: AINF | B3: 45657 | C3: AAPL | D3: APPLE INC | E3: EQUITY | F3: Information Technology | G3: Equity | H3: 742996.14 | I3: 4.95 | J3: 742996.14 | K3: 2967 | L3: 250.42 | M3: United States | N3: NASDAQ | O3: USD
A4: AINF | B4: 45657 | C4: CSCO | D4: CISCO SYSTEMS INC | E4: EQUITY | F4: Information Technology | G4: Equity | H4: 740177.6 | I4: 4.93 | J4: 740177.6 | K4: 12503 | L4: 59.2 | M4: United States | N4: NASDAQ | O4: USD
A5: AINF | B5: 45657 | C5: 2330 | D5: TAIWAN SEMICONDUCTOR MANUFACTURING | E5: EQUITY | F5: Information Technology | G5: Equity | H5: 739280.76 | I5: 4.93 | J5: 739280.76 | K5: 22546 | L5: 32.79 | M5: Taiwan | N5: Taiwan Stock Exchange | O5: TWD
A6: AINF | B6: 45657 | C6: ASML | D6: ASML HOLDING NV | E6: EQUITY | F6: Information Technology | G6: Equity | H6: 723174.87 | I6: 4.82 | J6: 723174.87 | K6: 1029 | L6: 702.79 | M6: Netherlands | N6: Euronext Amsterdam | O6: EUR
A7: AINF | B7: 45657 | C7: NVDA | D7: NVIDIA CORP | E7: EQUITY | F7: Information Technology | G7: Equity | H7: 719257.24 | I7: 4.8 | J7: 719257.24 | K7: 5356 | L7: 134.29 | M7: United States | N7: NASDAQ | O7: USD
A8: AINF | B8: 45657 | C8: AMZN | D8: AMAZON COM INC | E8: EQUITY | F8: Consumer Discretionary | G8: Equity | H8: 705338.85 | I8: 4.7 | J8: 705338.85 | K8: 3215 | L8: 219.39 | M8: United States | N8: NASDAQ | O8: USD
A9: AINF | B9: 45657 | C9: ORCL | D9: ORACLE CORP | E9: EQUITY | F9: Information Technology | G9: Equity | H9: 700054.64 | I9: 4.67 | J9: 700054.64 | K9: 4201 | L9: 166.64 | M9: United States | N9: New York Stock Exchange Inc. | O9: USD
A10: AINF | B10: 45657 | C10: IBM | D10: INTERNATIONAL BUSINESS MACHINES CO | E10: EQUITY | F10: Information Technology | G10: Equity | H10: 696641.27 | I10: 4.64 | J10: 696641.27 | K10: 3169 | L10: 219.83 | M10: United States | N10: New York Stock Exchange Inc. | O10: USD
A11: AINF | B11: 45657 | C11: MSFT | D11: MICROSOFT CORP | E11: EQUITY | F11: Information Technology | G11: Equity | H11: 689152.5 | I11: 4.59 | J11: 689152.5 | K11: 1635 | L11: 421.5 | M11: United States | N11: NASDAQ | O11: USD
A12: AINF | B12: 45657 | C12: AMD | D12: ADVANCED MICRO DEVICES INC | E12: EQUITY | F12: Information Technology | G12: Equity | H12: 680772.44 | I12: 4.54 | J12: 680772.44 | K12: 5636 | L12: 120.79 | M12: United States | N12: NASDAQ | O12: USD
A13: AINF | B13: 45657 | C13: QCOM | D13: QUALCOMM INC | E13: EQUITY | F13: Information Technology | G13: Equity | H13: 672087.5 | I13: 4.48 | J13: 672087.5 | K13: 4375 | L13: 153.62 | M13: United States | N13: NASDAQ | O13: USD
A14: AINF | B14: 45657 | C14: PLTR | D14: PALANTIR TECHNOLOGIES INC CLASS A | E14: EQUITY | F14: Information Technology | G14: Equity | H14: 650266.74 | I14: 4.34 | J14: 650266.74 | K14: 8598 | L14: 75.63 | M14: United States | N14: NASDAQ | O14: USD
A15: AINF | B15: 45657 | C15: 5930 | D15: SAMSUNG ELECTRONICS LTD | E15: EQUITY | F15: Information Technology | G15: Equity | H15: 601366.17 | I15: 4.01 | J15: 601366.17 | K15: 16641 | L15: 36.14 | M15: Korea (South) | N15: Korea Exchange (Stock Market) | O15: KRW
A16: AINF | B16: 45657 | C16: PANW | D16: PALO ALTO NETWORKS INC | E16: EQUITY | F16: Information Technology | G16: Equity | H16: 472550.12 | I16: 3.15 | J16: 472550.12 | K16: 2597 | L16: 181.96 | M16: United States | N16: NASDAQ | O16: USD
A17: AINF | B17: 45657 | C17: MRVL | D17: MARVELL TECHNOLOGY INC | E17: EQUITY | F17: Information Technology | G17: Equity | H17: 377076.3 | I17: 2.51 | J17: 377076.3 | K17: 3414 | L17: 110.45 | M17: United States | N17: NASDAQ | O17: USD
A18: AINF | B18: 45657 | C18: GOOGL | D18: ALPHABET INC CLASS A | E18: EQUITY | F18: Communication | G18: Equity | H18: 370649.4 | I18: 2.47 | J18: 370649.4 | K18: 1958 | L18: 189.3 | M18: United States | N18: NASDAQ | O18: USD
A19: AINF | B19: 45657 | C19: MU | D19: MICRON TECHNOLOGY INC | E19: EQUITY | F19: Information Technology | G19: Equity | H19: 367610.88 | I19: 2.45 | J19: 367610.88 | K19: 4368 | L19: 84.16 | M19: United States | N19: NASDAQ | O19: USD
A20: AINF | B20: 45657 | C20: GOOG | D20: ALPHABET INC CLASS C | E20: EQUITY | F20: Communication | G20: Equity | H20: 355741.92 | I20: 2.37 | J20: 355741.92 | K20: 1868 | L20: 190.44 | M20: United States | N20: NASDAQ | O20: USD
A21: AINF | B21: 45657 | C21: EQIX | D21: EQUINIX REIT INC | E21: EQUITY | F21: Real Estate | G21: Equity | H21: 352640.86 | I21: 2.35 | J21: 352640.86 | K21: 374 | L21: 942.89 | M21: United States | N21: NASDAQ | O21: USD
A22: AINF | B22: 45657 | C22: INTC | D22: INTEL CORPORATION CORP | E22: EQUITY | F22: Information Technology | G22: Equity | H22: 337702.15 | I22: 2.25 | J22: 337702.15 | K22: 16843 | L22: 20.05 | M22: United States | N22: NASDAQ | O22: USD
A23: AINF | B23: 45657 | C23: KLAC | D23: KLA CORP | E23: EQUITY | F23: Information Technology | G23: Equity | H23: 331443.12 | I23: 2.21 | J23: 331443.12 | K23: 526 | L23: 630.12 | M23: United States | N23: NASDAQ | O23: USD
A24: AINF | B24: 45657 | C24: 8035 | D24: TOKYO ELECTRON LTD | E24: EQUITY | F24: Information Technology | G24: Equity | H24: 292386.74 | I24: 1.95 | J24: 292386.74 | K24: 1900 | L24: 153.89 | M24: Japan | N24: Tokyo Stock Exchange | O24: JPY
A25: AINF | B25: 45657 | C25: 2454 | D25: MEDIATEK INC | E25: EQUITY | F25: Information Technology | G25: Equity | H25: 271048.82 | I25: 1.81 | J25: 271048.82 | K25: 6280 | L25: 43.16 | M25: Taiwan | N25: Taiwan Stock Exchange | O25: TWD
A26: AINF | B26: 45657 | C26: 2317 | D26: HON HAI PRECISION INDUSTRY LTD | E26: EQUITY | F26: Information Technology | G26: Equity | H26: 270574.2 | I26: 1.8 | J26: 270574.2 | K26: 48210 | L26: 5.61 | M26: Taiwan | N26: Taiwan Stock Exchange | O26: TWD
A27: AINF | B27: 45657 | C27: SNOW | D27: SNOWFLAKE INC | E27: EQUITY | F27: Information Technology | G27: Equity | H27: 204438.84 | I27: 1.36 | J27: 204438.84 | K27: 1324 | L27: 154.41 | M27: United States | N27: New York Stock Exchange Inc. | O27: USD
A28: AINF | B28: 45657 | C28: DELL | D28: DELL TECHNOLOGIES INC CLASS C | E28: EQUITY | F28: Information Technology | G28: Equity | H28: 144626.2 | I28: 0.96 | J28: 144626.2 | K28: 1255 | L28: 115.24 | M28: United States | N28: New York Stock Exchange Inc. | O28: USD
A29: AINF | B29: 45657 | C29: MCHP | D29: MICROCHIP TECHNOLOGY INC | E29: EQUITY | F29: Information Technology | G29: Equity | H29: 120779.1 | I29: 0.81 | J29: 120779.1 | K29: 2106 | L29: 57.35 | M29: United States | N29: NASDAQ | O29: USD
A30: AINF | B30: 45657 | C30: HPE | D30: HEWLETT PACKARD ENTERPRISE | E30: EQUITY | F30: Information Technology | G30: Equity | H30: 110166 | I30: 0.73 | J30: 110166 | K30: 5160 | L30: 21.35 | M30: United States | N30: New York Stock Exchange Inc. | O30: USD
A31: AINF | B31: 45657 | C31: NTAP | D31: NETAPP INC | E31: EQUITY | F31: Information Technology | G31: Equity | H31: 94256.96 | I31: 0.63 | J31: 94256.96 | K31: 812 | L31: 116.08 | M31: United States | N31: NASDAQ | O31: USD
A32: AINF | B32: 45657 | C32: PSTG | D32: PURE STORAGE INC CLASS A | E32: EQUITY | F32: Information Technology | G32: Equity | H32: 80104.72 | I32: 0.53 | J32: 80104.72 | K32: 1304 | L32: 61.43 | M32: United States | N32: New York Stock Exchange Inc. | O32: USD
A33: AINF | B33: 45657 | C33: ZBRA | D33: ZEBRA TECHNOLOGIES CORP CLASS A | E33: EQUITY | F33: Information Technology | G33: Equity | H33: 79175.1 | I33: 0.53 | J33: 79175.1 | K33: 205 | L33: 386.22 | M33: United States | N33: NASDAQ | O33: USD
A34: AINF | B34: 45657 | C34: 5935 | D34: SAMSUNG ELECTRONICS NON VOTING PRE | E34: EQUITY | F34: Information Technology | G34: Equity | H34: 78693.2 | I34: 0.52 | J34: 78693.2 | K34: 2621 | L34: 30.02 | M34: Korea (South) | N34: Korea Exchange (Stock Market) | O34: KRW
A35: AINF | B35: 45657 | C35: MDB | D35: MONGODB INC CLASS A | E35: EQUITY | F35: Information Technology | G35: Equity | H35: 68446.14 | I35: 0.46 | J35: 68446.14 | K35: 294 | L35: 232.81 | M35: United States | N35: NASDAQ | O35: USD
A36: AINF | B36: 45657 | C36: NTNX | D36: NUTANIX INC CLASS A | E36: EQUITY | F36: Information Technology | G36: Equity | H36: 65217.88 | I36: 0.43 | J36: 65217.88 | K36: 1066 | L36: 61.18 | M36: United States | N36: NASDAQ | O36: USD
A37: AINF | B37: 45657 | C37: JNPR | D37: JUNIPER NETWORKS INC | E37: EQUITY | F37: Information Technology | G37: Equity | H37: 49284.2 | I37: 0.33 | J37: 49284.2 | K37: 1316 | L37: 37.45 | M37: United States | N37: New York Stock Exchange Inc. | O37: USD
A38: AINF | B38: 45657 | C38: 992 | D38: LENOVO GROUP LTD | E38: EQUITY | F38: Information Technology | G38: Equity | H38: 44119.75 | I38: 0.29 | J38: 44119.75 | K38: 34000 | L38: 1.3 | M38: China | N38: Hong Kong Exchanges And Clearing Ltd | O38: HKD
A39: AINF | B39: 45657 | C39: CVLT | D39: COMMVAULT SYSTEMS INC | E39: EQUITY | F39: Information Technology | G39: Equity | H39: 25352.88 | I39: 0.17 | J39: 25352.88 | K39: 168 | L39: 150.91 | M39: United States | N39: NASDAQ | O39: USD
A40: AINF | B40: 45657 | C40: USD | D40: USD CASH | E40: CASH | F40: Cash and/or Derivatives | G40: Cash | H40: 6862.29 | I40: 0.05 | J40: 6862.29 | K40: 6862 | L40: 100 | M40: United States | N40: - | O40: USD
...

Sheet Sheet2
A1: Row Labels | B1: Dec | C1: Mar | D1: Apr | E1: May | F1: Variance
A2: MRVL | B2: 2.51 | C2: 1.61 | D2: 1.49 | E2: 1.47 | F2: -1.04
A3: AVGO | B3: 6.29 | C3: 4.2 | D3: 4.72 | E3: 5.36 | F3: -0.93
A4: AAPL | B4: 4.95 | C4: 5.08 | D4: 4.76 | E4: 4.05 | F4: -0.9
A5: CSCO | B5: 4.93 | C5: 4.96 | D5: 4.54 | E5: 4.48 | F5: -0.45
A6: QCOM | B6: 4.48 | C6: 4.85 | D6: 4.59 | E6: 4.14 | F6: -0.34
A7: 2330 | B7: 4.93 | C7: 4.48 | D7: 4.54 | E7: 4.67 | F7: -0.26
A8: ASML | B8: 4.82 | C8: 4.5 | D8: 4.46 | E8: 4.59 | F8: -0.23
A9: AMZN | B9: 4.7 | C9: 4.71 | D9: 4.46 | E9: 4.5 | F9: -0.2
A10: GOOG | B10: 2.37 | C10: 2.22 | D10: 2.24 | E10: 2.18 | F10: -0.19
A11: GOOGL | B11: 2.47 | C11: 2.33 | D11: 2.34 | E11: 2.29 | F11: -0.18
A12: IBM | B12: 4.64 | C12: 4.85 | D12: 4.62 | E12: 4.46 | F12: -0.18
A13: ZBRA | B13: 0.53 | C13: 0.44 | D13: 0.38 | E13: 0.4 | F13: -0.13
A14: HPE | B14: 0.73 | C14: 0.6 | D14: 0.62 | E14: 0.61 | F14: -0.12
A15: 2317 | B15: 1.8 | C15: 1.61 | D15: 1.59 | E15: 1.69 | F15: -0.11
A16: MDB | B16: 0.46 | C16: 0.39 | D16: 0.38 | E16: 0.37 | F16: -0.09
A17: NTAP | B17: 0.63 | C17: 0.54 | D17: 0.54 | E17: 0.54 | F17: -0.09
A18: PSTG | B18: 0.53 | C18: 0.44 | D18: 0.44 | E18: 0.47 | F18: -0.06
A19: EQIX | B19: 2.35 | C19: 2.4 | D19: 2.48 | E19: 2.31 | F19: -0.04
A20: KRW | B20: 0.04 | C20: 0.04 | D20: 0.04 | E20: 0.01 | F20: -0.03
A21: 2454 | B21: 1.81 | C21: 2.01 | D21: 1.98 | E21: 1.79 | F21: -0.02
A22: 992 | B22: 0.29 | C22: 0.35 | D22: 0.29 | E22: 0.27 | F22: -0.02
A23: JNPR | B23: 0.33 | C23: 0.36 | D23: 0.35 | E23: 0.32 | F23: -0.01
A24: EUR | B24: 0.02 | C24: 0.01 | D24: 0.02 | E24: 0.01 | F24: -0.01
A25: HKD | B25: 0.01 | C25: 0 | D25: 0 | E25: 0 | F25: -0.01
A26: TWD | B26: 0.03 | C26: 0.03 | D26: 0.03 | E26: 0.03 | F26: 0
A27: FSLY | B27: 0.03 | C27: 0.03 | D27: 0.02 | E27: 0.03 | F27: 0
A28: ICSUAGD | B28: 0.02 | C28: 0.02 | D28: 0.02 | E28: 0.02 | F28: 0
A29: HWBM5 | C29: 0 | D29: 0 | E29: 0 | F29: 0
A30: ORCL | B30: 4.67 | C30: 4.54 | D30: 4.47 | E30: 4.68 | F30: 0.01
A31: 2388 | B31: 0.01 | C31: 0.02 | D31: 0.02 | E31: 0.02 | F31: 0.01
A32: 5935 | B32: 0.52 | C32: 0.58 | D32: 0.58 | E32: 0.53 | F32: 0.01
A33: MCHP | B33: 0.81 | C33: 0.78 | D33: 0.73 | E33: 0.83 | F33: 0.02
A34: CITFT | C34: 0.02 | D34: 0.02 | E34: 0.02 | F34: 0.02
A35: DELL | B35: 0.96 | C35: 0.88 | D35: 0.87 | E35: 0.98 | F35: 0.02
A36: CVLT | B36: 0.17 | C36: 0.2 | D36: 0.21 | E36: 0.2 | F36: 0.03
A37: JPY | B37: 0 | C37: 0.03 | D37: 0.03 | E37: 0.03 | F37: 0.03
A38: Grand Total | B38: 99.97 | C38: 100 | D38: 99.98 | E38: 100.02 | F38: 0.05
A39: 5930 | B39: 4.01 | C39: 4.42 | D39: 4.3 | E39: 4.06 | F39: 0.05
A40: INTC | B40: 2.25 | C40: 2.93 | D40: 2.53 | E40: 2.31 | F40: 0.06
...

Sheet WQTM
A1: Date | B1: Fund Name | C1: Fund Ticker Symbol | D1: Security Description | E1: Security Ticker | F1: Shares | G1: Mkt Value | H1: Weight %
A2: 2026-02-05T00:00:00 | B2: WisdomTree Quantum Computing UCITS ETF - USD Acc | C2: WQTM LN | D2: D-Wave Quantum Inc | E2: QBTS US | F2: 358772 | G2: 6174466.1 | H2: 0.0452234
A3: 2026-02-05T00:00:00 | B3: WisdomTree Quantum Computing UCITS ETF - USD Acc | C3: WQTM LN | D3: Intel Corp | E3: INTC UQ | F3: 125789 | G3: 6068061.4 | H3: 0.044444
A4: 2026-02-05T00:00:00 | B4: WisdomTree Quantum Computing UCITS ETF - USD Acc | C4: WQTM LN | D4: Ionq Inc | E4: IONQ US | F4: 184908 | G4: 5626750.4 | H4: 0.0412118
A5: 2026-02-05T00:00:00 | B5: WisdomTree Quantum Computing UCITS ETF - USD Acc | C5: WQTM LN | D5: Google Inc | E5: GOOGL UQ | F5: 16210 | G5: 5369562.5 | H5: 0.0393281
A6: 2026-02-05T00:00:00 | B6: WisdomTree Quantum Computing UCITS ETF - USD Acc | C6: WQTM LN | D6: Quantum Computing Inc | E6: QUBT US | F6: 642910 | G6: 5021127.1 | H6: 0.036776
A7: 2026-02-05T00:00:00 | B7: WisdomTree Quantum Computing UCITS ETF - USD Acc | C7: WQTM LN | D7: Rigetti Computing Inc | E7: RGTI US | F7: 332925 | G7: 4985551.9 | H7: 0.0365155
A8: 2026-02-05T00:00:00 | B8: WisdomTree Quantum Computing UCITS ETF - USD Acc | C8: WQTM LN | D8: SK Telecom Co Ltd | E8: 017670 KS | F8: 94349 | G8: 4979262.7 | H8: 0.0364694
A9: 2026-02-05T00:00:00 | B9: WisdomTree Quantum Computing UCITS ETF - USD Acc | C9: WQTM LN | D9: International Business Machines Corp | E9: IBM UN | F9: 14809 | G9: 4292981 | H9: 0.0314429
A10: 2026-02-05T00:00:00 | B10: WisdomTree Quantum Computing UCITS ETF - USD Acc | C10: WQTM LN | D10: Amazon.com Inc | E10: AMZN UQ | F10: 19063 | G10: 4245139.5 | H10: 0.0310925
A11: 2026-02-05T00:00:00 | B11: WisdomTree Quantum Computing UCITS ETF - USD Acc | C11: WQTM LN | D11: Fujitsu Ltd | E11: 6702 JT | F11: 167846 | G11: 4221167.4 | H11: 0.0309169
A12: 2026-02-05T00:00:00 | B12: WisdomTree Quantum Computing UCITS ETF - USD Acc | C12: WQTM LN | D12: Nvidia Corp | E12: NVDA UQ | F12: 24336 | G12: 4182871.7 | H12: 0.0306364
A13: 2026-02-05T00:00:00 | B13: WisdomTree Quantum Computing UCITS ETF - USD Acc | C13: WQTM LN | D13: Honeywell International Inc | E13: HON UN | F13: 17385 | G13: 4065482.2 | H13: 0.0297766
... A38: 2026-02-05T00:00:00 | B38: WisdomTree Quantum Computing UCITS ETF - USD Acc | C38: WQTM LN | D38: Cadence Design Systems Inc | E38: CDNS UQ | F38: 7719 | G38: 2085210.7 | H38: 0.0152726
A39: 2026-02-05T00:00:00 | B39: WisdomTree Quantum Computing UCITS ETF - USD Acc | C39: WQTM LN | D39: CASH W-O | F39: 0 | H39: 0.0024155
A40: 2026-02-05T00:00:00 | B40: WisdomTree Quantum Computing UCITS ETF - USD Acc | C40: WQTM LN | D40: EURO INCOME A/C | F40: 0 | H40: 0.0002176
A41: 2026-02-05T00:00:00 | B41: WisdomTree Quantum Computing UCITS ETF - USD Acc | C41: WQTM LN | D41: JAPANESE YEN | F41: 0 | H41: 3.81e-05
A42: 2026-02-06T00:00:00 | B42: WisdomTree Quantum Computing UCITS ETF - USD Acc | C42: WQTM LN | D42: D-Wave Quantum Inc | E42: QBTS US | F42: 355714 | G42: 7370394.1 | H42: 0.0517432
A43: 2026-02-06T00:00:00 | B43: WisdomTree Quantum Computing UCITS ETF - USD Acc | C43: WQTM LN | D43: Ionq Inc | E43: IONQ US | F43: 183332 | G43: 6414786.7 | H43: 0.0450344
A44: 2026-02-06T00:00:00 | B44: WisdomTree Quantum Computing UCITS ETF - USD Acc | C44: WQTM LN | D44: Intel Corp | E44: INTC UQ | F44: 124717 | G44: 6309433 | H44: 0.0442948
A45: 2026-02-06T00:00:00 | B45: WisdomTree Quantum Computing UCITS ETF - USD Acc | C45: WQTM LN | D45: Quantum Computing Inc | E45: QUBT US | F45: 637430 | G45: 6010964.9 | H45: 0.0421994
A46: 2026-02-06T00:00:00 | B46: WisdomTree Quantum Computing UCITS ETF - USD Acc | C46: WQTM LN | D46: Rigetti Computing Inc | E46: RGTI US | F46: 330087 | G46: 5845840.8 | H46: 0.0410402
A47: 2026-02-06T00:00:00 | B47: WisdomTree Quantum Computing UCITS ETF - USD Acc | C47: WQTM LN | D47: Google Inc | E47: GOOGL UQ | F47: 16072 | G47: 5189005.9 | H47: 0.0364289
A48: 2026-02-06T00:00:00 | B48: WisdomTree Quantum Computing UCITS ETF - USD Acc | C48: WQTM LN | D48: Nvidia Corp | E48: NVDA UQ | F48: 24128 | G48: 4473572.5 | H48: 0.0314063
A49: 2026-02-06T00:00:00 | B49: WisdomTree Quantum Computing UCITS ETF - USD Acc | C49: WQTM LN | D49: SK Telecom Co Ltd | E49: 017670 KS | F49: 93545 | G49: 4405263 | H49: 0.0309267
A50: 2026-02-06T00:00:00 | B50: WisdomTree Quantum Computing UCITS ETF - USD Acc | C50: WQTM LN | D50: International Business Machines Corp | E50: IBM UN | F50: 14683 | G50: 4389189.2 | H50: 0.0308139
A51: 2026-02-06T00:00:00 | B51: WisdomTree Quantum Computing UCITS ETF - USD Acc | C51: WQTM LN | D51: Formfactor Inc | E51: FORM | F51: 47520 | G51: 4290580.8 | H51: 0.0301216
A52: 2026-02-06T00:00:00 | B52: WisdomTree Quantum Computing UCITS ETF - USD Acc | C52: WQTM LN | D52: Fujitsu Ltd | E52: 6702 JT | F52: 166416 | G52: 4151514.5 | H52: 0.0291453
A53: 2026-02-06T00:00:00 | B53: WisdomTree Quantum Computing UCITS ETF - USD Acc | C53: WQTM LN | D53: Skywater Technology Inc | E53: SKYT US | F53: 136408 | G53: 4139982.8 | H53: 0.0290644
... A78: 2026-02-06T00:00:00 | B78: WisdomTree Quantum Computing UCITS ETF - USD Acc | C78: WQTM LN | D78: Cadence Design Systems Inc | E78: CDNS UQ | F78: 7653 | G78: 2169778.6 | H78: 0.0152327
A79: 2026-02-06T00:00:00 | B79: WisdomTree Quantum Computing UCITS ETF - USD Acc | C79: WQTM LN | D79: CASH W-O | F79: 0 | H79: 0.0082112
A80: 2026-02-06T00:00:00 | B80: WisdomTree Quantum Computing UCITS ETF - USD Acc | C80: WQTM LN | D80: EURO INCOME A/C | F80: 0 | H80: 0.000209
A81: 2026-02-06T00:00:00 | B81: WisdomTree Quantum Computing UCITS ETF - USD Acc | C81: WQTM LN | D81: JAPANESE YEN | F81: 0 | H81: 3.65e-05
A82: 2026-02-19T00:00:00 | B82: WisdomTree Quantum Computing UCITS ETF - USD Acc | C82: WQTM LN | D82: D-Wave Quantum Inc | E82: QBTS US | F82: 361830 | G82: 7012265.4 | H82: 0.0489311
A83: 2026-02-19T00:00:00 | B83: WisdomTree Quantum Computing UCITS ETF - USD Acc | C83: WQTM LN | D83: Ionq Inc | E83: IONQ US | F83: 186484 | G83: 6234160.1 | H83: 0.0435016
A84: 2026-02-19T00:00:00 | B84: WisdomTree Quantum Computing UCITS ETF - USD Acc | C84: WQTM LN | D84: Intel Corp | E84: INTC UQ | F84: 126861 | G84: 5660537.8 | H84: 0.0394989
A85: 2026-02-19T00:00:00 | B85: WisdomTree Quantum Computing UCITS ETF - USD Acc | C85: WQTM LN | D85: Rigetti Computing Inc | E85: RGTI US | F85: 335763 | G85: 5573665.8 | H85: 0.0388927
A86: 2026-02-19T00:00:00 | B86: WisdomTree Quantum Computing UCITS ETF - USD Acc | C86: WQTM LN | D86: Quantum Computing Inc | E86: QUBT US | F86: 648390 | G86: 5329765.8 | H86: 0.0371908
A87: 2026-02-19T00:00:00 | B87: WisdomTree Quantum Computing UCITS ETF - USD Acc | C87: WQTM LN | D87: SK Telecom Co Ltd | E87: 017670 KS | F87: 93545 | G87: 5273330.3 | H87: 0.036797
A88: 2026-02-19T00:00:00 | B88: WisdomTree Quantum Computing UCITS ETF - USD Acc | C88: WQTM LN | D88: Google Inc | E88: GOOGL UQ | F88: 16348 | G88: 4950991.8 | H88: 0.0345477
...

Sheet NATP
A1: FUND | B1: Date | C1: Security Description | D1: Shares | E1: Market Value (Base) | F1: Trading Currency | G1: SEDOL/CUSIP | H1: Exposure Country | I1: Region | J1: ISIN | K1: Weight
A2: NATP | B2: 46030 | C2: BAE SYSTEMS PLC | D2: 5957482 | E2: 1.6199677e+08 | F2: GBP | G2: 0263494 | H2: United Kingdom | I2: Europe | J2: GB0002634946 | K2: 0.0524
A3: NATP | B3: 46030 | C3: RHEINMETALL AG COMMON | D3: 72130 | E3: 1.5585088e+08 | F3: EUR | G3: 5334588 | H3: Germany | I3: Europe | J3: DE0007030009 | K3: 0.0504 | P3: Column Labels
A4: NATP | B4: 46030 | C4: SAFRAN SA COMMON STOCK | D4: 416860 | E4: 1.5543098e+08 | F4: EUR | G4: B058TZ6 | H4: France | I4: Europe | J4: FR0000073272 | K4: 0.0503 | P4: Sum of Shares | X4: Sum of Weight
A5: NATP | B5: 46030 | C5: RTX CORP | D5: 753100 | E5: 140957727 | F5: USD | G5: BM5M5Y3 | H5: United States | I5: North America | J5: US75513E1010 | K5: 0.0456 | O5: Row Labels | P5: 46030 | Q5: 46031 | R5: 46049 | S5: 46055 | T5: 46058 | U5: 46059 | V5: 46063 | W5: (blank) | X5: 46030 | Y5: 46031 | Z5: 46049 | AA5: 46055 | AB5: 46058 | AC5: 46059 | AD5: 46063 | AE5: (blank)
A6: NATP | B6: 46030 | C6: LOCKHEED MARTIN CORP | D6: 266213 | E6: 1.3801547e+08 | F6: USD | G6: 2522096 | H6: United States | I6: North America | J6: US5398301094 | K6: 0.0447 | O6: CISCO SYSTEMS INC COMMON | P6: 1842989 | Q6: 1842989 | R6: 1836765 | S6: 1912860 | T6: 1916102 | U6: 1914481 | V6: 1945280 | X6: 0.0443 | Y6: 0.0434 | Z6: 0.0448 | AA6: 0.0498 | AB6: 0.0533 | AC6: 0.0535 | AD6: 0.0539
A7: NATP | B7: 46030 | C7: CISCO SYSTEMS INC COMMON | D7: 1842989 | E7: 1.3695137e+08 | F7: USD | G7: 2198163 | H7: United States | I7: North America | J7: US17275R1023 | K7: 0.0443 | O7: SAFRAN SA COMMON STOCK | P7: 416860 | Q7: 416860 | R7: 417214 | S7: 428028 | T7: 428754 | U7: 428391 | V7: 435288 | X7: 0.0503 | Y7: 0.0489 | Z7: 0.0477 | AA7: 0.0492 | AB7: 0.0516 | AC7: 0.0514 | AD7: 0.0504
A8: NATP | B8: 46030 | C8: GENERAL DYNAMICS CORP | D8: 382507 | E8: 1.3442826e+08 | F8: USD | G8: 2365161 | H8: United States | I8: North America | J8: US3695501086 | K8: 0.0435 | O8: LOCKHEED MARTIN CORP | P8: 266213 | Q8: 266213 | R8: 265313 | S8: 243566 | T8: 243978 | U8: 243772 | V8: 247686 | X8: 0.0447 | Y8: 0.0459 | Z8: 0.0489 | AA8: 0.05 | AB8: 0.0502 | AC8: 0.0501 | AD8: 0.05
A9: NATP | B9: 46030 | C9: NORTHROP GRUMMAN CORP | D9: 217408 | E9: 1.2844247e+08 | F9: USD | G9: 2648806 | H9: United States | I9: North America | J9: US6668071029 | K9: 0.0416 | O9: BAE SYSTEMS PLC | P9: 5957482 | Q9: 5957482 | R9: 5937362 | S9: 5710841 | T9: 5720517 | U9: 5715679 | V9: 5807601 | X9: 0.0524 | Y9: 0.0521 | Z9: 0.0509 | AA9: 0.0483 | AB9: 0.0485 | AC9: 0.0482 | AD9: 0.0482
A10: NATP | B10: 46030 | C10: PALANTIR TECHNOLOGIES INC | D10: 717975 | E10: 1.2698106e+08 | F10: USD | G10: BN78DQ4 | H10: United States | I10: North America | J10: US69608A1088 | K10: 0.0411 | O10: NORTHROP GRUMMAN CORP | P10: 217408 | Q10: 217408 | R10: 216672 | S10: 213462 | T10: 213824 | U10: 213643 | V10: 217082 | X10: 0.0416 | Y10: 0.0427 | Z10: 0.0456 | AA10: 0.0472 | AB10: 0.0503 | AC10: 0.0499 | AD10: 0.0477
A11: NATP | B11: 46030 | C11: CROWDSTRIKE HOLDINGS INC | D11: 258612 | E11: 1.1996235e+08 | F11: USD | G11: BJJP138 | H11: United States | I11: North America | J11: US22788C1053 | K11: 0.0388 | O11: GENERAL DYNAMICS CORP | P11: 382507 | Q11: 382507 | R11: 381215 | S11: 390645 | T11: 391307 | U11: 390976 | V11: 397265 | X11: 0.0435 | Y11: 0.043 | Z11: 0.0435 | AA11: 0.0438 | AB11: 0.0467 | AC11: 0.0464 | AD11: 0.0457
A12: NATP | B12: 46030 | C12: PALO ALTO NETWORKS INC | D12: 607839 | E12: 1.1597568e+08 | F12: USD | G12: B87ZMX0 | H12: United States | I12: North America | J12: US6974351057 | K12: 0.0375 | O12: RTX CORP | P12: 753100 | Q12: 753100 | R12: 750556 | S12: 714547 | T12: 715757 | U12: 715152 | V12: 726647 | X12: 0.0456 | Y12: 0.0451 | Z12: 0.0468 | AA12: 0.0464 | AB12: 0.0474 | AC12: 0.0468 | AD12: 0.0455
A13: NATP | B13: 46030 | C13: L3HARRIS TECHNOLOGIES INC | D13: 354078 | E13: 1.1533737e+08 | F13: USD | G13: BK9DTN5 | H13: United States | I13: North America | J13: US5024311095 | K13: 0.0373 | O13: RHEINMETALL AG COMMON | P13: 72130 | Q13: 72130 | R13: 71886 | S13: 70920 | T13: 71040 | U13: 70980 | V13: 72120 | X13: 0.0504 | Y13: 0.0507 | Z13: 0.0493 | AA13: 0.0467 | AB13: 0.0445 | AC13: 0.0444 | AD13: 0.0442
A14: NATP | B14: 46030 | C14: THALES SA COMMON STOCK | D14: 362783 | E14: 1.124974e+08 | F14: EUR | G14: 4162791 | H14: France | I14: Europe | J14: FR0000121329 | K14: 0.0364 | O14: CROWDSTRIKE HOLDINGS INC | P14: 258612 | Q14: 258612 | R14: 259140 | S14: 316916 | T14: 317452 | U14: 317184 | V14: 322276 | X14: 0.0388 | Y14: 0.0387 | Z14: 0.0383 | AA14: 0.0449 | AB14: 0.0405 | AC14: 0.0413 | AD14: 0.0428
A15: NATP | B15: 46030 | C15: FORTINET INC COMMON STOCK | D15: 1211505 | E15: 94557965 | F15: USD | G15: B5B2106 | H15: United States | I15: North America | J15: US34959E1091 | K15: 0.0306 | O15: PALO ALTO NETWORKS INC | P15: 607839 | Q15: 607839 | R15: 609259 | S15: 762296 | T15: 763588 | U15: 762942 | V15: 775216 | X15: 0.0375 | Y15: 0.0365 | Z15: 0.0346 | AA15: 0.0432 | AB15: 0.0399 | AC15: 0.04 | AD15: 0.0412
A16: NATP | B16: 46030 | C16: LEONARDO SPA COMMON STOCK | D16: 1113326 | E16: 76009391 | F16: EUR | G16: B0DJNG0 | H16: Italy | I16: Europe | J16: IT0003856405 | K16: 0.0246 | O16: L3HARRIS TECHNOLOGIES INC | P16: 354078 | Q16: 354078 | R16: 352882 | S16: 345070 | T16: 345654 | U16: 345362 | V16: 350910 | X16: 0.0373 | Y16: 0.0378 | Z16: 0.0394 | AA16: 0.0379 | AB16: 0.04 | AC16: 0.0398 | AD16: 0.0389
A17: NATP | B17: 46030 | C17: SAAB AB COMMON STOCK SEK | D17: 1016770 | E17: 70941632 | F17: SEK | G17: BPXZH27 | H17: Sweden | I17: Europe | J17: SE0021921269 | K17: 0.023 | O17: PALANTIR TECHNOLOGIES INC | P17: 717975 | Q17: 717975 | R17: 715551 | S17: 832514 | T17: 833924 | U17: 833219 | V17: 846614 | X17: 0.0411 | Y17: 0.0405 | Z17: 0.0367 | AA17: 0.0397 | AB17: 0.0366 | AC17: 0.0373 | AD17: 0.0379
... A55: NATP | B55: 46030 | C55: SENTINELONE INC COMMON | D55: 574085 | E55: 8800723.1 | F55: USD | G55: BP7L1B8 | H55: United States | I55: North America | J55: US81730H1095 | K55: 0.0028 | O55: LIG NEX1 CO LTD COMMON | P55: 34038 | Q55: 34038 | R55: 33922 | S55: 32202 | T55: 32256 | U55: 32229 | V55: 32742 | X55: 0.004 | Y55: 0.004 | Z55: 0.0037 | AA55: 0.0032 | AB55: 0.0032 | AC55: 0.0031 | AD55: 0.0033
A56: NATP | B56: 46030 | C56: HANWHA SYSTEMS CO LTD | D56: 202069 | E56: 8400386.6 | F56: KRW | G56: BJN3H96 | H56: South Korea | I56: Asia | J56: KR7272210006 | K56: 0.0027 | O56: BIGBEAR.AI HOLDINGS INC | S56: 2138610 | T56: 2142234 | U56: 2140422 | V56: 2174850 | AA56: 0.0032 | AB56: 0.003 | AC56: 0.0034 | AD56: 0.0032
A57: NATP | B57: 46030 | C57: VARONIS SYSTEMS INC | D57: 202718 | E57: 7247168.5 | F57: USD | G57: BJZ2ZR5 | H57: United States | I57: North America | J57: US9222801022 | K57: 0.0023 | O57: MERCURY SYSTEMS INC | P57: 110565 | Q57: 110565 | R57: 110193 | S57: 109307 | T57: 109493 | U57: 109400 | V57: 111167 | X57: 0.0032 | Y57: 0.0033 | Z57: 0.0034 | AA57: 0.0033 | AB57: 0.0029 | AC57: 0.003 | AD57: 0.003
A58: NATP | B58: 46030 | C58: BLACKBERRY LTD COMMON | D58: 1612604 | E58: 6224651.4 | F58: USD | G58: BCBHZ42 | H58: Canada | I58: North America | J58: CA09228F1036 | K58: 0.002 | O58: SCIENCE APPLICATIONS | P58: 86663 | Q58: 86663 | R58: 86371 | S58: 82748 | T58: 82888 | U58: 82818 | V58: 84148 | X58: 0.0031 | Y58: 0.0031 | Z58: 0.0028 | AA58: 0.0027 | AB58: 0.0027 | AC58: 0.0027 | AD58: 0.0026
A59: NATP | B59: 46030 | C59: DRONESHIELD LTD COMMON | D59: 2408606 | E59: 6211608.2 | F59: AUD | G59: BYV1JW4 | H59: Australia | I59: Asia | J59: AU000000DRO2 | K59: 0.002 | O59: SENTINELONE INC COMMON | P59: 574085 | Q59: 574085 | R59: 572145 | S59: 583277 | T59: 584265 | U59: 583771 | V59: 593157 | X59: 0.0028 | Y59: 0.0028 | Z59: 0.0027 | AA59: 0.0027 | AB59: 0.0026 | AC59: 0.0025 | AD59: 0.0026
A60: NATP | B60: 46030 | C60: LEONARDO DRS INC COMMON | D60: 147732 | E60: 5737910.9 | F60: USD | G60: BNSNZQ2 | H60: United States | I60: North America | J60: US52661A1088 | K60: 0.0019 | O60: QUALYS INC COMMON STOCK | P60: 67795 | Q60: 67795 | R60: 67567 | S60: 65496 | T60: 65606 | U60: 65551 | V60: 66596 | X60: 0.0029 | Y60: 0.0029 | Z60: 0.0028 | AA60: 0.0029 | AB60: 0.0028 | AC60: 0.0024 | AD60: 0.0024
A61: NATP | B61: 46030 | C61: TENABLE HOLDINGS INC | D61: 225508 | E61: 5312968.5 | F61: USD | G61: BF7J7N6 | H61: United States | I61: North America | J61: US88025T1025 | K61: 0.0017 | O61: TENABLE HOLDINGS INC | P61: 225508 | Q61: 225508 | R61: 252398 | S61: 290561 | T61: 291053 | U61: 290807 | V61: 295481 | X61: 0.0017 | Y61: 0.0017 | Z61: 0.0018 | AA61: 0.0021 | AB61: 0.0019 | AC61: 0.002 | AD61: 0.0022
A62: NATP | B62: 46030 | C62: CASH | D62: 3.9337081e+08 | E62: 5527736.7 | F62: USD | G62: CASH | H62: Cash | I62: Cash | J62: NONE | K62: 0.0017 | O62: LEONARDO DRS INC COMMON | P62: 147732 | Q62: 147732 | R62: 147232 | S62: 150978 | T62: 151234 | U62: 151106 | V62: 153538 | X62: 0.0019 | Y62: 0.0019 | Z62: 0.0019 | AA62: 0.002 | AB62: 0.0019 | AC62: 0.0019 | AD62: 0.0019
A63: NATP | B63: 46030 | C63: KONGSBERG GRUPPEN ASA | D63: 0 | E63: 69959.96 | F63: NOK | G63: 5208241 | H63: Norway | I63: Europe | J63: NO0003043309 | K63: 0 | O63: DRONESHIELD LTD COMMON | P63: 2408606 | Q63: 2408606 | R63: 2400470 | S63: 2477036 | T63: 2481234 | U63: 2479135 | V63: 2519016 | X63: 0.002 | Y63: 0.0021 | Z63: 0.0022 | AA63: 0.0019 | AB63: 0.0019 | AC63: 0.0017 | AD63: 0.0019
A64: NATP | B64: 46030 | C64: INVISIO AB COMMON STOCK | D64: 0 | E64: 4505.35 | F64: SEK | G64: B06G108 | H64: Sweden | I64: Europe | J64: SE0001200015 | K64: 0 | O64: VARONIS SYSTEMS INC | P64: 202718 | Q64: 202718 | R64: 202034 | S64: 208367 | T64: 208721 | U64: 208544 | V64: 211907 | X64: 0.0023 | Y64: 0.0023 | Z64: 0.0021 | AA64: 0.002 | AB64: 0.0016 | AC64: 0.0016 | AD64: 0.0018
A65: NATP | B65: 46030 | C65: SAAB AB COMMON STOCK SEK | D65: 0 | E65: 3114.03 | F65: SEK | G65: 5469554 | H65: Sweden | I65: Europe | J65: SE0021921269 | K65: 0 | O65: FIREFLY AEROSPACE INC | R65: 20432 | S65: 209349 | T65: 209703 | U65: 209526 | V65: 212889 | Z65: 0.0002 | AA65: 0.0015 | AB65: 0.0016 | AC65: 0.0016 | AD65: 0.0016
A66: NATP | B66: 46031 | C66: BAE SYSTEMS PLC | D66: 5957482 | E66: 1.6411779e+08 | F66: GBP | G66: 0263494 | H66: United Kingdom | I66: Europe | J66: GB0002634946 | K66: 0.0521 | O66: KYNDRYL HOLDINGS INC | P66: 430049 | Q66: 430049 | R66: 428597 | S66: 414510 | T66: 415212 | U66: 414861 | V66: 421530 | X66: 0.0038 | Y66: 0.0037 | Z66: 0.0032 | AA66: 0.0031 | AB66: 0.0031 | AC66: 0.0032 | AD66: 0.0015
A67: NATP | B67: 46031 | C67: RHEINMETALL AG COMMON | D67: 72130 | E67: 1.5962459e+08 | F67: EUR | G67: 5334588 | H67: Germany | I67: Europe | J67: DE0007030009 | K67: 0.0507 | O67: SOFTCAT PLC COMMON STOCK | P67: 776159 | Q67: 776159 | R67: 606729 | X67: 0.0049 | Y67: 0.0049 | Z67: 0.0042
A68: NATP | B68: 46031 | C68: SAFRAN SA COMMON STOCK | D68: 416860 | E68: 1.5397513e+08 | F68: EUR | G68: B058TZ6 | H68: France | I68: Europe | J68: FR0000073272 | K68: 0.0489 | O68: (blank)
A69: NATP | B69: 46031 | C69: LOCKHEED MARTIN CORP | D69: 266213 | E69: 1.4453236e+08 | F69: USD | G69: 2522096 | H69: United States | I69: North America | J69: US5398301094 | K69: 0.0459 | O69: BLACKBERRY LTD COMMON | P69: 1612604 | Q69: 1612604 | R69: 1607156 | X69: 0.002 | Y69: 0.002 | Z69: 0.0019
A70: NATP | B70: 46031 | C70: RTX CORP | D70: 753100 | E70: 141959350 | F70: USD | G70: BM5M5Y3 | H70: United States | I70: North America | J70: US75513E1010 | K70: 0.0451 | O70: INVISIO AB COMMON STOCK | P70: 0 | Q70: 0 | R70: 0 | S70: 0 | T70: 0 | U70: 0 | V70: 0 | X70: 0 | Y70: 0 | Z70: 0 | AA70: 0 | AB70: 0 | AC70: 0 | AD70: 0
A71: NATP | B71: 46031 | C71: CISCO SYSTEMS INC COMMON | D71: 1842989 | E71: 1.3680394e+08 | F71: USD | G71: 2198163 | H71: United States | I71: North America | J71: US17275R1023 | K71: 0.0434 | O71: Grand Total | P71: 4.3133086e+08 | Q71: 4.2522973e+08 | R71: 4.2228223e+08 | S71: 4.2169753e+08 | T71: 4.2444565e+08 | U71: 4.2254209e+08 | V71: 4.7197714e+08 | X71: 0.9993 | Y71: 1.0002 | Z71: 0.9996 | AA71: 1.0014 | AB71: 1.0015 | AC71: 1.0018 | AD71: 1.0011
A72: NATP | B72: 46031 | C72: GENERAL DYNAMICS CORP | D72: 382507 | E72: 1.353654e+08 | F72: USD | G72: 2365161 | H72: United States | I72: North America | J72: US3695501086 | K72: 0.043
A73: NATP | B73: 46031 | C73: NORTHROP GRUMMAN CORP | D73: 217408 | E73: 1.3453642e+08 | F73: USD | G73: 2648806 | H73: United States | I73: North America | J73: US6668071029 | K73: 0.0427
A74: NATP | B74: 46031 | C74: PALANTIR TECHNOLOGIES INC | D74: 717975 | E74: 1.2743338e+08 | F74: USD | G74: BN78DQ4 | H74: United States | I74: North America | J74: US69608A1088 | K74: 0.0405
A75: NATP | B75: 46031 | C75: CROWDSTRIKE HOLDINGS INC | D75: 258612 | E75: 1.2170539e+08 | F75: USD | G75: BJJP138 | H75: United States | I75: North America | J75: US22788C1053 | K75: 0.0387
A76: NATP | B76: 46031 | C76: L3HARRIS TECHNOLOGIES INC | D76: 354078 | E76: 1.1888877e+08 | F76: USD | G76: BK9DTN5 | H76: United States | I76: North America | J76: US5024311095 | K76: 0.0378
A77: NATP | B77: 46031 | C77: PALO ALTO NETWORKS INC | D77: 607839 | E77: 1.1489373e+08 | F77: USD | G77: B87ZMX0 | H77: United States | I77: North America | J77: US6974351057 | K77: 0.0365
...

Sheet FCBR
A1: ETF | B1: Date | C1: Security Name | D1: Identifier | E1: CUSIP | F1: Classification | G1: Shares or Quantity | H1: Market Value | I1: Weighting
A2: FCBR | B2: 46072 | C2: Cisco Systems, Inc. | D2: CSCO | E2: 17275R102 | F2: Telecommunications Equipment | G2: 11527970 | H2: 9.0563732e+08 | I2: 0.0905
A3: FCBR | B3: 46072 | C3: Infosys Limited (ADR) | D3: INFY | E3: 456788108 | F3: Software and Computer Services | G3: 50741475 | H3: 7.3828846e+08 | I3: 0.0737
A4: FCBR | B4: 46072 | C4: Broadcom Inc. | D4: AVGO | E4: 11135F101 | F4: Technology Hardware and Equipment | G4: 2201131 | H4: 7.3515574e+08 | I4: 0.0734
A5: FCBR | B5: 46072 | C5: CrowdStrike Holdings, Inc. (Class A) | D5: CRWD | E5: 22788C105 | F5: Software and Computer Services | G5: 1741994 | H5: 7.3536535e+08 | I5: 0.0734
A6: FCBR | B6: 46072 | C6: Palo Alto Networks, Inc. | D6: PANW | E6: 697435105 | F6: Software and Computer Services | G6: 4665039 | H6: 7.0437424e+08 | I6: 0.0704
A7: FCBR | B7: 46072 | C7: Thales S.A. | D7: HO.FP | E7: F9156M108 | F7: Aerospace and Defense | G7: 1695338 | H7: 5.2532256e+08 | I7: 0.0525
A8: FCBR | B8: 46072 | C8: Akamai Technologies, Inc. | D8: AKAM | E8: 00971T101 | F8: Software and Computer Services | G8: 4564948 | H8: 5.0027265e+08 | I8: 0.05
A9: FCBR | B9: 46072 | C9: F5, Inc. | D9: FFIV | E9: 315616102 | F9: Software and Computer Services | G9: 1638407 | H9: 4.5742685e+08 | I9: 0.0457
A10: FCBR | B10: 46072 | C10: Fortinet, Inc. | D10: FTNT | E10: 34959E109 | F10: Software and Computer Services | G10: 5466283 | H10: 4.4643133e+08 | I10: 0.0446
A11: FCBR | B11: 46072 | C11: Cloudflare, Inc. (Class A) | D11: NET | E11: 18915M107 | F11: Software and Computer Services | G11: 2215072 | H11: 4.2671147e+08 | I11: 0.0426
A12: FCBR | B12: 46072 | C12: Leidos Holdings, Inc. | D12: LDOS | E12: 525327102 | F12: Software and Computer Services | G12: 2320676 | H12: 4.0906556e+08 | I12: 0.0409
A13: FCBR | B13: 46072 | C13: Okta, Inc. | D13: OKTA | E13: 679295105 | F13: Software and Computer Services | G13: 4912366 | H13: 4.0183154e+08 | I13: 0.0401
... A30: FCBR | B30: 46072 | C30: Radware Ltd. | D30: RDWR | E30: M81873107 | F30: Software and Computer Services | G30: 1361183 | H30: 34084022 | I30: 0.0034
A31: FCBR | B31: 46072 | C31: US Dollar | D31: $USD | F31: Other | G31: 19980827 | H31: 19980827 | I31: 0.002
A32: FCBR | B32: 46072 | C32: Rapid7, Inc. | D32: RPD | E32: 753422104 | F32: Software and Computer Services | G32: 2026443 | H32: 14367481 | I32: 0.0014
A33: FCBR | B33: 46072 | C33: OneSpan Inc. | D33: OSPN | E33: 68287N100 | F33: Software and Computer Services | G33: 1161918 | H33: 13222627 | I33: 0.0013
A34: FCBR | B34: 46072 | C34: NCC Group Plc | D34: NCC.LN | E34: G64319109 | F34: Software and Computer Services | G34: 6663320 | H34: 11818721 | I34: 0.0012
A35: FCBR | B35: 46072 | C35: Japanese Yen | D35: $JPY | F35: Other | G35: 815712305 | H35: 5263339.2 | I35: 0.0005
A36: FCBR | B36: 46072 | C36: Canadian Dollar | D36: $CAD | F36: Other | G36: 1 | H36: 0.38 | I36: 0
A37: FCBR | B37: 46077 | C37: Cisco Systems, Inc. | D37: CSCO | E37: 17275R102 | F37: Telecommunications Equipment | G37: 11459660 | H37: 8.9545783e+08 | I37: 0.0964
A38: FCBR | B38: 46077 | C38: Broadcom Inc. | D38: AVGO | E38: 11135F101 | F38: Technology Hardware and Equipment | G38: 2188081 | H38: 7.1219848e+08 | I38: 0.0767
A39: FCBR | B39: 46077 | C39: Infosys Limited (ADR) | D39: INFY | E39: 456788108 | F39: Software and Computer Services | G39: 50440839 | H39: 6.9810121e+08 | I39: 0.0751
A40: FCBR | B40: 46077 | C40: Palo Alto Networks, Inc. | D40: PANW | E40: 697435105 | F40: Software and Computer Services | G40: 4637391 | H40: 6.5697918e+08 | I40: 0.0707
A41: FCBR | B41: 46077 | C41: CrowdStrike Holdings, Inc. (Class A) | D41: CRWD | E41: 22788C105 | F41: Software and Computer Services | G41: 1731680 | H41: 606520920 | I41: 0.0653
A42: FCBR | B42: 46077 | C42: Thales S.A. | D42: HO.FP | E42: F9156M108 | F42: Aerospace and Defense | G42: 1685294 | H42: 498552397 | I42: 0.0537
A43: FCBR | B43: 46077 | C43: Akamai Technologies, Inc. | D43: AKAM | E43: 00971T101 | F43: Software and Computer Services | G43: 4537894 | H43: 4.5437933e+08 | I43: 0.0489
A44: FCBR | B44: 46077 | C44: F5, Inc. | D44: FFIV | E44: 315616102 | F44: Software and Computer Services | G44: 1628705 | H44: 4.4305662e+08 | I44: 0.0477
A45: FCBR | B45: 46077 | C45: Fortinet, Inc. | D45: FTNT | E45: 34959E109 | F45: Software and Computer Services | G45: 5433901 | H45: 4.0879237e+08 | I45: 0.044
A46: FCBR | B46: 46077 | C46: Leidos Holdings, Inc. | D46: LDOS | E46: 525327102 | F46: Software and Computer Services | G46: 2306924 | H46: 4.0170468e+08 | I46: 0.0432
A47: FCBR | B47: 46077 | C47: Gen Digital Inc. | D47: GEN | E47: 668771108 | F47: Software and Computer Services | G47: 16717977 | H47: 3.6729395e+08 | I47: 0.0395
A48: FCBR | B48: 46077 | C48: Cloudflare, Inc. (Class A) | D48: NET | E48: 18915M107 | F48: Software and Computer Services | G48: 2201950 | H48: 3.6070143e+08 | I48: 0.0388
... A65: FCBR | B65: 46077 | C65: Radware Ltd. | D65: RDWR | E65: M81873107 | F65: Software and Computer Services | G65: 1353119 | H65: 30235444 | I65: 0.0033
A66: FCBR | B66: 46077 | C66: US Dollar | D66: $USD | F66: Other | G66: 20390272 | H66: 20390272 | I66: 0.0022
A67: FCBR | B67: 46077 | C67: OneSpan Inc. | D67: OSPN | E67: 68287N100 | F67: Software and Computer Services | G67: 1155042 | H67: 12520655 | I67: 0.0013
A68: FCBR | B68: 46077 | C68: Rapid7, Inc. | D68: RPD | E68: 753422104 | F68: Software and Computer Services | G68: 2014437 | H68: 12328354 | I68: 0.0013
A69: FCBR | B69: 46077 | C69: NCC Group Plc | D69: NCC.LN | E69: G64319109 | F69: Software and Computer Services | G69: 6623846 | H69: 11552388 | I69: 0.0012
A70: FCBR | B70: 46077 | C70: Japanese Yen | D70: $JPY | F70: Other | G70: 815712305 | H70: 5232279 | I70: 0.0006
A71: FCBR | B71: 46077 | C71: Canadian Dollar | D71: $CAD | F71: Other | G71: -127240 | H71: -92875.77 | I71: 0

Sheet AINF
A1: As Of | B1: Currency | C1: NAV | D1: Securities In Issue | E1: Net Assets | F1: Fund Return Series | G1: Benchmark Return Series
A2: 45631 | B2: USD | C2: 5.104953 | D2: 1000000 | E2: 5104953.8 | F2: 100 | G2: 100
A3: 45632 | B3: USD | C3: 5.149099 | D3: 1000000 | E3: 5149099.2 | F3: 100.86477 | G3: --
A4: 45635 | B4: USD | C4: 5.089238 | D4: 1000000 | E4: 5089238.4 | F4: 99.692162 | G4: 99.698046
A5: 45636 | B5: USD | C5: 5.019961 | D5: 1000000 | E5: 5019961.1 | F5: 98.335107 | G5: 98.334664
A6: 45637 | B6: USD | C6: 5.093328 | D6: 1000000 | E6: 5093328.6 | F6: 99.77228 | G6: 99.779436
A7: 45638 | B7: USD | C7: 5.090522 | D7: 2000000 | E7: 10181046 | F7: 99.717314 | G7: 99.726666
A8: 45639 | B8: USD | C8: 5.14664 | D8: 2000000 | E8: 10293281 | F8: 100.8166 | G8: 100.82887
A9: 45642 | B9: USD | C9: 5.215882 | D9: 2000000 | E9: 10431765 | F9: 102.17297 | G9: 102.1904
A10: 45643 | B10: USD | C10: 5.169691 | D10: 2000000 | E10: 10339383 | F10: 101.26814 | G10: 101.28601
A11: 45644 | B11: USD | C11: 5.017739 | D11: 2000000 | E11: 10035479 | F11: 98.291581 | G11: 98.310358
A12: 45645 | B12: USD | C12: 4.975434 | D12: 2000000 | E12: 9950868.9 | F12: 97.462876 | G12: 97.479071
A13: 45646 | B13: USD | C13: 5.029401 | D13: 2000000 | E13: 10058803 | F13: 98.520026 | G13: 98.535717
A14: 45649 | B14: USD | C14: 5.10432 | D14: 3000000 | E14: 15312961 | F14: 99.9876 | G14: 100.00936
A15: 45650 | B15: USD | C15: 5.158891 | D15: 3000000 | E15: 15476674 | F15: -- | G15: 101.08076
A16: 45653 | B16: USD | C16: 5.106835 | D16: 3000000 | E16: 15320506 | F16: -- | G16: 100.0357
A17: 45656 | B17: USD | C17: 5.035062 | D17: 3000000 | E17: 15105188 | F17: 98.630918 | G17: 98.63017
A18: 45657 | B18: USD | C18: 4.999048 | D18: 3000000 | E18: 14997145 | F18: 97.925446 | G18: 97.924306
A19: 45659 | B19: USD | C19: 5.006017 | D19: 3000000 | E19: 15018052 | F19: 98.061961 | G19: 98.06143
A20: 45660 | B20: USD | C20: 5.091241 | D20: 3000000 | E20: 15273725 | F20: 99.731398 | G20: 99.729729
A21: 45663 | B21: USD | C21: 5.182584 | D21: 3000000 | E21: 15547752 | F21: 101.5207 | G21: 101.52741
A22: 45664 | B22: USD | C22: 5.125954 | D22: 5000000 | E22: 25629772 | F22: 100.41138 | G22: 100.41783
A23: 45665 | B23: USD | C23: 5.099735 | D23: 5000000 | E23: 25498677 | F23: 99.897786 | G23: 99.903589
A24: 45666 | B24: USD | C24: 5.089847 | D24: 5000000 | E24: 25449238 | F24: 99.704091 | G24: 99.709439
A25: 45667 | B25: USD | C25: 4.999266 | D25: 5000000 | E25: 24996331 | F25: 97.929716 | G25: 97.931471
A26: 45670 | B26: USD | C26: 4.941926 | D26: 5000000 | E26: 24709634 | F26: 96.806494 | G26: 96.809066
A27: 45671 | B27: USD | C27: 4.960522 | D27: 5000000 | E27: 24802612 | F27: 97.170767 | G27: 97.174915
A28: 45672 | B28: USD | C28: 5.042492 | D28: 5000000 | E28: 25212465 | F28: 98.776463 | G28: 98.781415
... A120: 45806 | B120: USD | C120: 5.152362 | D120: 13000000 | E120: 66980714 | F120: 100.92869 | G120: 100.9898
A121: 45807 | B121: USD | C121: 5.14747 | D121: 13000000 | E121: 66917112 | F121: -- | G121: --
A122: 45810 | B122: USD | C122: 5.188353 | D122: 13000000 | E122: 67448600 | F122: 101.63371 | G122: 101.69773
A123: 45811 | B123: USD | C123: 5.245902 | D123: 14000000 | E123: 73442634 | F123: 102.76102 | G123: 102.82748
A124: 45812 | B124: USD | C124: 5.277068 | D124: 14000000 | E124: 73878954 | F124: -- | G124: --
A125: 45813 | B125: USD | C125: 5.268026 | D125: 14000000 | E125: 73752372 | F125: 103.19441 | G125: 103.26037
A126: 45814 | B126: USD | C126: 5.329753 | D126: 14000000 | E126: 74616554 | F126: 104.40357 | G126: 104.47282
A127: 45817 | B127: USD | C127: 5.395965 | D127: 14000000 | E127: 75543518 | F127: 105.70058 | G127: 105.77606
A128: 45818 | B128: USD | C128: 5.444568 | D128: 14000000 | E128: 76223966 | F128: 106.65266 | G128: 106.73153
A129: 45819 | B129: USD | C129: 5.452358 | D129: 14000000 | E129: 76333013 | F129: 106.80525 | G129: 106.88639
A130: 45820 | B130: USD | C130: 5.494308 | D130: 14000000 | E130: 76920323 | F130: 107.627 | G130: 107.71069
A131: 45821 | B131: USD | C131: 5.437612 | D131: 16000000 | E131: 87001795 | F131: 106.5164 | G131: 106.60336
...

Sheet DFEU
A1: As Of | B1: Currency | C1: NAV | D1: Securities In Issue | E1: Net Assets | F1: Fund Return Series | G1: Benchmark Return Series
A2: 45800 | B2: EUR | C2: 4.997688 | D2: 1000000 | E2: 4997688 | F2: 100 | G2: 100
A3: 45804 | B3: EUR | C3: 5.200417 | D3: 1000000 | E3: 5200418 | F3: 104.05646 | G3: 104.06211
A4: 45805 | B4: EUR | C4: 5.278065 | D4: 1000000 | E4: 5278065.7 | F4: -- | G4: --
A5: 45806 | B5: EUR | C5: 5.229013 | D5: 1000000 | E5: 5229013 | F5: 100 | G5: --
A6: 45807 | B6: EUR | C6: 5.238507 | D6: 1000000 | E6: 5238508 | F6: 104.81861 | G6: 104.82883
A7: 45810 | B7: EUR | C7: 5.249557 | D7: 1000000 | E7: 5249557.4 | F7: 105.03971 | G7: 105.05248
A8: 45811 | B8: EUR | C8: 5.338457 | D8: 1000000 | E8: 5338457.4 | F8: 106.81853 | G8: 106.83721
A9: 45812 | B9: EUR | C9: 5.309253 | D9: 1000000 | E9: 5309253.3 | F9: -- | G9: --
A10: 45813 | B10: EUR | C10: 5.42492 | D10: 1000000 | E10: 5424920.3 | F10: 108.54859 | G10: 108.5731
A11: 45814 | B11: EUR | C11: 5.283128 | D11: 1000000 | E11: 5283128.6 | F11: 105.71144 | G11: 105.73178
A12: 45817 | B12: EUR | C12: 5.21695 | D12: 3000000 | E12: 15650852 | F12: 104.38727 | G12: 104.0822
A13: 45818 | B13: EUR | C13: 4.943732 | D13: 3000000 | E13: 14831198 | F13: 98.920381 | G13: 98.915245
A14: 45819 | B14: EUR | C14: 5.004662 | D14: 3000000 | E14: 15013987 | F14: 100.13954 | G14: 100.1496
A15: 45820 | B15: EUR | C15: 5.023171 | D15: 3000000 | E15: 15069515 | F15: 100.5099 | G15: 100.52208
A16: 45821 | B16: EUR | C16: 5.083784 | D16: 3000000 | E16: 15251354 | F16: 101.72272 | G16: 101.73903
A17: 45824 | B17: EUR | C17: 5.079014 | D17: 4000000 | E17: 20316057 | F17: 101.62727 | G17: 101.64613
A18: 45825 | B18: EUR | C18: 5.070118 | D18: 4000000 | E18: 20280472 | F18: 101.44927 | G18: 101.47018
A19: 45826 | B19: EUR | C19: 5.081187 | D19: 4000000 | E19: 20324751 | F19: 101.67075 | G19: 101.69371
A20: 45827 | B20: EUR | C20: 5.026417 | D20: 4000000 | E20: 20105671 | F20: 100.57485 | G20: 100.59828
A21: 45828 | B21: EUR | C21: 5.058063 | D21: 4000000 | E21: 20232253 | F21: 101.20806 | G21: 101.23362
... A66: 45891 | B66: EUR | C66: 4.946638 | D66: 12000000 | E66: 59359667 | F66: 98.978528 | G66: 99.085674
A67: 45895 | B67: EUR | C67: 4.991731 | D67: -- | E67: -- | F67: 99.880805 | G67: 99.997571
A68: 45896 | B68: EUR | C68: 4.988731 | D68: 12000000 | E68: 59864775 | F68: 99.820777 | G68: 99.939058
A69: 45897 | B69: EUR | C69: 4.987553 | D69: 12000000 | E69: 59850639 | F69: 99.797206 | G69: 99.914641
A70: 45898 | B70: EUR | C70: 5.013645 | D70: 12000000 | E70: 60163749 | F70: 100.31929 | G70: 100.44227
A71: 45901 | B71: EUR | C71: 5.129651 | D71: 12000000 | E71: 61555823 | F71: 102.64048 | G71: 102.77325
A72: 45902 | B72: EUR | C72: 5.028534 | D72: 12000000 | E72: 60342412 | F72: 100.6172 | G72: 100.74896
A73: 45903 | B73: EUR | C73: 5.079878 | D73: 12000000 | E73: 60958542 | F73: 101.64456 | G73: 101.77885
A74: 45904 | B74: EUR | C74: 5.001845 | D74: 12000000 | E74: 60022145 | F74: 100.08318 | G74: 100.211
A75: 45905 | B75: EUR | C75: 5.022353 | D75: 12000000 | E75: 60268248 | F75: 100.49353 | G75: 100.62336
A76: 45908 | B76: EUR | C76: 5.09434 | D76: 13000000 | E76: 66226423 | F76: 101.93393 | G76: 102.07074
A77: 45909 | B77: EUR | C77: 5.077488 | D77: 14000000 | E77: 71084833 | F77: 101.59674 | G77: 101.73346
A78: 45910 | B78: EUR | C78: 5.191861 | D78: 14000000 | E78: 72686054 | F78: 103.88526 | G78: 104.03065
A79: 45911 | B79: EUR | C79: 5.349187 | D79: 14000000 | E79: 74888622 | F79: 107.03323 | G79: 107.1884
... A149: 46009 | B149: EUR | C149: 4.949497 | D149: 26000000 | E149: 1.2868693e+08 | F149: 99.035734 | G149: 99.241365
A150: 46010 | B150: EUR | C150: 4.994457 | D150: 26000000 | E150: 129855902 | F150: -- | G150: 100.14283
A151: 46013 | B151: EUR | C151: 4.988333 | D151: 26000000 | E151: 1.2969668e+08 | F151: 99.812813 | G151: 100.0237
A152: 46014 | B152: EUR | C152: 5.005782 | D152: 26000000 | E152: 1.3015036e+08 | F152: 100.16196 | G152: 100.37407
A153: 46015 | B153: EUR | C153: 5.00429 | D153: 26000000 | E153: 1.3011155e+08 | F153: 100.1321 | G153: 100.34453
...

Sheet MINE
A1: As Of | B1: Currency | C1: NAV | D1: Securities In Issue | E1: Net Assets | F1: Fund Return Series | G1: Benchmark Return Series
A2: 45098 | B2: USD | C2: 4.913997 | D2: 1000000 | E2: 4913997.9 | F2: 100 | G2: 100
A3: 45099 | B3: USD | C3: 4.884557 | D3: 1000000 | E3: 4884557.8 | F3: 99.400895 | G3: --
A4: 45100 | B4: USD | C4: 4.761274 | D4: 1000000 | E4: 4761274.8 | F4: 96.892082 | G4: 96.910707
A5: 45103 | B5: USD | C5: 4.814387 | D5: 1000000 | E5: 4814388 | F5: 97.972933 | G5: 97.999065
A6: 45104 | B6: USD | C6: 4.841511 | D6: 1000000 | E6: 4841511.1 | F6: 98.524908 | G6: 98.565022
A7: 45105 | B7: USD | C7: 4.747385 | D7: 1000000 | E7: 4747385.1 | F7: 96.60944 | G7: 96.659486
A8: 45106 | B8: USD | C8: 4.731446 | D8: 1000000 | E8: 4731446.4 | F8: 96.285081 | G8: 96.334738
A9: 45107 | B9: USD | C9: 4.790157 | D9: 1000000 | E9: 4790157.9 | F9: 97.479852 | G9: 97.50049
A10: 45110 | B10: USD | C10: 4.873975 | D10: 1000000 | E10: 4873975.3 | F10: 99.185551 | G10: 99.201815
A11: 45111 | B11: USD | C11: 4.901299 | D11: 1000000 | E11: 4901299.8 | F11: 99.741595 | G11: 99.785007
